Workbook

Sheet INPUTS
B2: HOJA DE ENTRADA DE DATOS — MÉTODO LP TRAINING
B3: Rellena solo las celdas amarillas. Todo lo demás se calcula y se traslada al informe automáticamente.
B5: 1. DATOS DEL CLIENTE Y MES
B6: Nombre del cliente: | C6: JAIME MARTINEZ | E6: Mes del informe: | F6: MARZO
B7: Distancia objetivo: | C7: MEDIA MARATÓN - ULTRA | E7: Año: | F7: 2025
B8: Fecha inicio plan: | C8: 28/07/2025 | E8: Número del mes (1-12): | F8: 3
B10: 2. RESUMEN GENERAL DEL MES
B11: Entrenos PROGRAMADOS: | C11: 24 | E11: Entrenos COMPLETADOS: | F11: 14
B12: Kilómetros TOTALES (km): | C12: 64.7 | E12: Desnivel acumulado (m): | F12: 280
B13: Horas totales (HH:MM:SS): | C13: 11:45:36 | E13: Rodaje más largo del mes (km): | F13: 14.2
B14: Las horas se introducen en formato texto HH:MM:SS (ej: 11:45:36).
B16: 3. DATOS DEL MES ANTERIOR (para comparación)
B17: Distancia mes anterior (km): | C17: 77.1 | E17: Tiempo mes anterior (HH:MM:SS): | F17: 9:19:55
B18: Ritmo medio mes anterior (MM:SS): | C18: 07:16 | E18: Rodaje más largo mes anterior (km): | F18: 42.8
B19: Ritmo medio mes actual (MM:SS): | C19: 05:11
B21: 4. KILÓMETROS Y HORAS POR SEMANA
B22: SEMANA | C22: KILÓMETROS | E22: SEMANA | F22: HORAS (HH:MM:SS)
B23: S 1 (2 a 8) | C23: 24.7 | E23: S 1 (2 a 8) | F23: 4:49:32
B24: S 2 (9 a 15) | C24: 29.2 | E24: S 2 (9 a 15) | F24: 4:55:00
B25: S 3 (16 a 22) | C25: 10.8 | E25: S 3 (16 a 22) | F25: 1:05:00
B26: S 4 (23 a 29) | C26: 0 | E26: S 4 (23 a 29) | F26: 0:55:00
B27: S 5 (30-fin) | C27: 0 | E27: S 5 (30-fin) | F27: 0:00:00
B28: La S5 solo se usa cuando el mes tiene 5 semanas parciales (rellena con 0 si no aplica).
B30: 5. TIEMPO EN ZONAS DE VELOCIDAD (en %)
B31: ZONA | C31: % TIEMPO | E31: ZONA | F31: % TIEMPO
B32: Z0 | C32: 1.34 | E32: Z3 | F32: 3.12
B33: Z1 | C33: 34.3 | E33: Z3+ | F33: 1.47
B34: Z1+ | C34: 44.7 | E34: Z4 | F34: 0.23
B35: Z2 | C35: 13.8 | E35: Z5 | F35: 1.08
B36: TOTAL (debe ser ≈ 100): | C36: =SUM(C32:C35)+SUM(F32:F35) | D36: Si no suma ≈100, revisa los porcentajes
B38: 6. TIEMPO EN ZONAS DE FRECUENCIA CARDIACA (en %)
B39: ZONA | C39: % TIEMPO | E39: ZONA | F39: % TIEMPO
B40: Z0 | C40: 1.54 | E40: Z3 | F40: 13.9
B41: Z1 | C41: 4.21 | E41: Z3+ | F41: 0
B42: Z1+ | C42: 6.9 | E42: Z4 | F42: 0
B43: Z2 | C43: 18.6 | E43: Z5 | F43: 0
B44: TOTAL (debe ser ≈ 100): | C44: =SUM(C40:C43)+SUM(F40:F43) | D44: Si no suma ≈100, revisa los porcentajes
B46: 7. COMENTARIOS DEL ENTRENADOR
B47: Resumen del mes:
B48: Cerramos un mes de Marzo un tanto complicado, donde no terminamos de encontrar el punto en cuanto a situaciones personales, lesiones y demás. Llegados a este punto, para mí es muy importante que me des feedback de cómo te vas sintiendo y cómo se va desarrollando todo. Me encanta que cuando las cosas van bien, me des ese feedback que la realidad es que regularmente ha sido así, pero ahora que todo está un tanto irregular, cobra mucho más sentido que me expreses todo para buscar una solución, porque de lo contrario, vamos dando "palos de ciego" como aquél que dice. Ánimo con todo y lo dicho, sabes que siempre estoy disponible para ti y mi objetivo siempre es brindarte toda la ayuda que necesites en cualquier momento.
...

Sheet INFORME MENSUAL
B2: MÉTODO LP TRAINING
B3: Lorenzo Pla · Entrenador de corredores online · @LP.RTRAINING_
B5: =CONCATENATE("REPORTE MENSUAL · ", INPUTS!F6, " ", INPUTS!F7)
B7: =CONCATENATE("ATLETA: ", INPUTS!C6) | F7: =CONCATENATE("OBJETIVO: ", INPUTS!C7) | J7: =CONCATENATE("INICIO PLAN: ", INPUTS!C8)
B9: ADHERENCIA AL PLAN | E9: KM TOTALES | H9: HORAS ENTRENADAS | K9: DESNIVEL ACUMULADO
B10: =IFERROR(INPUTS!F11/INPUTS!C11,0) | E10: =INPUTS!C12 | H10: =INPUTS!C13 | K10: =CONCATENATE(INPUTS!F12," m")
B11: =CONCATENATE(INPUTS!F11," / ",INPUTS!C11," entrenos") | E11: completados este mes | H11: tiempo total acumulado | K11: metros positivos
B13: EVOLUCIÓN DEL RENDIMIENTO vs MES ANTERIOR
B14: MÉTRICA | E14: MES ANTERIOR | G14: MES ACTUAL | I14: VARIACIÓN | K14: VARIACIÓN %
B15: Distancia Completada (km) | E15: =INPUTS!C17 | G15: =INPUTS!C12 | I15: =IFERROR(G15-E15,"—") | K15: =IFERROR((G15-E15)/E15,"—")
B16: Tiempo Total | E16: =INPUTS!F17 | G16: =INPUTS!C13 | I16: =IFERROR(TEXT(ABS(TIMEVALUE(G16)-TIMEVALUE(E16)),IF(TIMEVALUE(G16)>=TIMEVALUE(E16),"+[h]:mm:ss","-[h]:mm:ss")),"—") | K16: =IFERROR((TIMEVALUE(G16)-TIMEVALUE(E16))/TIMEVALUE(E16),"—")
B17: Ritmo Medio (min/km) | E17: =INPUTS!C18 | G17: =INPUTS!C19 | I17: =IFERROR(TEXT(ABS(TIMEVALUE("0:"&G17)-TIMEVALUE("0:"&E17)),IF(TIMEVALUE("0:"&G17)>=TIMEVALUE("0:"&E17),"+m:ss","-m:ss")),"—") | K17: =IFERROR((TIMEVALUE("0:"&G17)-TIMEVALUE("0:"&E17))/TIMEVALUE("0:"&E17),"—")
B18: Rodaje más Largo (km) | E18: =INPUTS!F18 | G18: =INPUTS!F13 | I18: =IFERROR(G18-E18,"—") | K18: =IFERROR((G18-E18)/E18,"—")
B20: KILÓMETROS POR SEMANA | H20: HORAS POR SEMANA
B37: TIEMPO EN ZONAS DE VELOCIDAD (%) | H37: TIEMPO EN ZONAS DE FRECUENCIA CARDIACA (%)
B54: PROFORMA DEL INFORME: Lorenzo Pla Estébanez · Método LP Training

Sheet RESUMEN ANUAL
B2: MÉTODO LP TRAINING
B3: Lorenzo Pla · Entrenador de corredores online · @LP.RTRAINING_
B5: =CONCATENATE("RESUMEN ANUAL · ", INPUTS!F7)
B7: =CONCATENATE("ATLETA: ", INPUTS!C6, " · OBJETIVO: ", INPUTS!C7, " · INICIO PLAN: ", INPUTS!C8)
B9: KM ACUMULADOS DEL AÑO | F9: MEDIA MENSUAL (KM) | J9: MEJOR MES (KM)
B10: =SUM(_chart_data!J2:J13) | F10: =IFERROR(SUMIF(_chart_data!J2:J13,">0")/COUNTIF(_chart_data!J2:J13,">0"),0) | J10: =MAX(_chart_data!J2:J13)
B11: acumulado en el año | F11: de los meses con actividad | J11: pico de volumen del año
B13: KILÓMETROS TOTALES POR MES
B33: COMENTARIOS DEL ENTRENADOR
B34: =INPUTS!B48
B43: PRÓXIMOS PASOS / OBJETIVOS DEL MES QUE VIENE
B44: =INPUTS!B56
B54: PROFORMA DEL INFORME: Lorenzo Pla Estébanez · Método LP Training

Sheet _chart_data
A1: Semana | B1: KM | C1: Horas | E1: Zona | F1: Velocidad | G1: FFCC | I1: Mes | J1: KM
A2: =INPUTS!B23 | B2: =INPUTS!C23 | C2: =IFERROR(TIMEVALUE(INPUTS!F23)*24,0) | E2: Z0 | F2: =INPUTS!C32 | G2: =INPUTS!C40 | I2: ENE | J2: =INPUTS!C65
A3: =INPUTS!B24 | B3: =INPUTS!C24 | C3: =IFERROR(TIMEVALUE(INPUTS!F24)*24,0) | E3: Z1 | F3: =INPUTS!C33 | G3: =INPUTS!C41 | I3: FEB | J3: =INPUTS!C66
A4: =INPUTS!B25 | B4: =INPUTS!C25 | C4: =IFERROR(TIMEVALUE(INPUTS!F25)*24,0) | E4: Z1+ | F4: =INPUTS!C34 | G4: =INPUTS!C42 | I4: MAR | J4: =INPUTS!C67
A5: =INPUTS!B26 | B5: =INPUTS!C26 | C5: =IFERROR(TIMEVALUE(INPUTS!F26)*24,0) | E5: Z2 | F5: =INPUTS!C35 | G5: =INPUTS!C43 | I5: ABR | J5: =INPUTS!C68
A6: =INPUTS!B27 | B6: =INPUTS!C27 | C6: =IFERROR(TIMEVALUE(INPUTS!F27)*24,0) | E6: Z3 | F6: =INPUTS!F32 | G6: =INPUTS!F40 | I6: MAY | J6: =INPUTS!C69
E7: Z3+ | F7: =INPUTS!F33 | G7: =INPUTS!F41 | I7: JUN | J7: =INPUTS!C70
E8: Z4 | F8: =INPUTS!F34 | G8: =INPUTS!F42 | I8: JUL | J8: =INPUTS!F65
E9: Z5 | F9: =INPUTS!F35 | G9: =INPUTS!F43 | I9: AGO | J9: =INPUTS!F66
I10: SEP | J10: =INPUTS!F67
I11: OCT | J11: =INPUTS!F68
I12: NOV | J12: =INPUTS!F69
I13: DIC | J13: =INPUTS!F70
